Traceback (most recent call last):
  File "/Library/Frameworks/Python.framework/Versions/3.7/lib/python3.7/site-packages/urllib3/connection.py", line 160, in _new_conn
    (self._dns_host, self.port), self.timeout, **extra_kw
  File "/Library/Frameworks/Python.framework/Versions/3.7/lib/python3.7/site-packages/urllib3/util/connection.py", line 61, in create_connection
    for res in socket.getaddrinfo(host, port, family, socket.SOCK_STREAM):
  File "/Library/Frameworks/Python.framework/Versions/3.7/lib/python3.7/socket.py", line 748, in getaddrinfo
    for res in _socket.getaddrinfo(host, port, family, type, proto, flags):
socket.gaierror: [Errno 8] nodename nor servname provided, or not known

During handling of the above exception, another exception occurred:

Traceback (most recent call last):
  File "/Library/Frameworks/Python.framework/Versions/3.7/lib/python3.7/site-packages/urllib3/connectionpool.py", line 677, in urlopen
    chunked=chunked,
  File "/Library/Frameworks/Python.framework/Versions/3.7/lib/python3.7/site-packages/urllib3/connectionpool.py", line 381, in _make_request
    self._validate_conn(conn)
  File "/Library/Frameworks/Python.framework/Versions/3.7/lib/python3.7/site-packages/urllib3/connectionpool.py", line 976, in _validate_conn
    conn.connect()
  File "/Library/Frameworks/Python.framework/Versions/3.7/lib/python3.7/site-packages/urllib3/connection.py", line 308, in connect
    conn = self._new_conn()
  File "/Library/Frameworks/Python.framework/Versions/3.7/lib/python3.7/site-packages/urllib3/connection.py", line 172, in _new_conn
    self, "Failed to establish a new connection: %s" % e
urllib3.exceptions.NewConnectionError: <urllib3.connection.HTTPSConnection object at 0x7f8dd9022048>: Failed to establish a new connection: [Errno 8] nodename nor servname provided, or not known

During handling of the above exception, another exception occurred:

Traceback (most recent call last):
  File "/Library/Frameworks/Python.framework/Versions/3.7/lib/python3.7/site-packages/requests/adapters.py", line 449, in send
    timeout=timeout
  File "/Library/Frameworks/Python.framework/Versions/3.7/lib/python3.7/site-packages/urllib3/connectionpool.py", line 725, in urlopen
    method, url, error=e, _pool=self, _stacktrace=sys.exc_info()[2]
  File "/Library/Frameworks/Python.framework/Versions/3.7/lib/python3.7/site-packages/urllib3/util/retry.py", line 439, in increment
    raise MaxRetryError(_pool, url, error or ResponseError(cause))
urllib3.exceptions.MaxRetryError: HTTPSConnectionPool(host='graphql.bitquery.io', port=443): Max retries exceeded with url: / (Caused by NewConnectionError('<urllib3.connection.HTTPSConnection object at 0x7f8dd9022048>: Failed to establish a new connection: [Errno 8] nodename nor servname provided, or not known'))

During handling of the above exception, another exception occurred:

Traceback (most recent call last):
  File "whale_watch_app.py", line 44, in <module>
    schedule.run_pending()
  File "/Library/Frameworks/Python.framework/Versions/3.7/lib/python3.7/site-packages/schedule/__init__.py", line 592, in run_pending
    default_scheduler.run_pending()
  File "/Library/Frameworks/Python.framework/Versions/3.7/lib/python3.7/site-packages/schedule/__init__.py", line 94, in run_pending
    self._run_job(job)
  File "/Library/Frameworks/Python.framework/Versions/3.7/lib/python3.7/site-packages/schedule/__init__.py", line 147, in _run_job
    ret = job.run()
  File "/Library/Frameworks/Python.framework/Versions/3.7/lib/python3.7/site-packages/schedule/__init__.py", line 491, in run
    ret = self.job_func()
  File "whale_watch_app.py", line 32, in job
    updated_whale_data = whale_watch.process_bitquery(time_segment, limit, 'whale_conf.json', alert_phone_nums, tw)
  File "/Users/patrickskelley/Desktop/Programming/Projects/Coin/Coin/whale_watch.py", line 130, in process_bitquery
    bit_query = get_bitquery_data(time_interval, limit)
  File "/Users/patrickskelley/Desktop/Programming/Projects/Coin/Coin/whale_watch.py", line 125, in get_bitquery_data
    resp = requests.post("https://graphql.bitquery.io/", data=payload)
  File "/Library/Frameworks/Python.framework/Versions/3.7/lib/python3.7/site-packages/requests/api.py", line 119, in post
    return request('post', url, data=data, json=json, **kwargs)
  File "/Library/Frameworks/Python.framework/Versions/3.7/lib/python3.7/site-packages/requests/api.py", line 61, in request
    return session.request(method=method, url=url, **kwargs)
  File "/Library/Frameworks/Python.framework/Versions/3.7/lib/python3.7/site-packages/requests/sessions.py", line 530, in request
    resp = self.send(prep, **send_kwargs)
  File "/Library/Frameworks/Python.framework/Versions/3.7/lib/python3.7/site-packages/requests/sessions.py", line 643, in send
    r = adapter.send(request, **kwargs)
  File "/Library/Frameworks/Python.framework/Versions/3.7/lib/python3.7/site-packages/requests/adapters.py", line 516, in send
    raise ConnectionError(e, request=request)
requests.exceptions.ConnectionError: HTTPSConnectionPool(host='graphql.bitquery.io', port=443): Max retries exceeded with url: / (Caused by NewConnectionError('<urllib3.connection.HTTPSConnection object at 0x7f8dd9022048>: Failed to establish a new connection: [Errno 8] nodename nor servname provided, or not known'))
